Workbook
Name lista: Alumnos!$A:$XES

Sheet Verano2024
A1: Marca temporal | B1: Dirección de correo electrónico | C1: Nombre completo | D1: Correo Electrónico | E1: Edad | F1: DNI | G1: Domicilio (localidad) | H1: Cel de contacto | I1: Talleres | J1: Abonar inscripción Alias: folklore.ma (Titular: Graciela Silva)
A2: 45317.679 | B2: luchagana1@gmail.com | C2: Gianna victoria viera troil | D2: Luchagana1@gmail.com | E2: 6 | F2: 56719844 | G2: Astrada 508 | H2: 3754401018 | I2: Manualidades para niños | J2: Alias: avance.giro.final (titular: Graciela Silva)
A3: 45317.683 | B3: luchagana1@gmail.com | C3: Luana sherlyn viera troil | D3: Luchagana1@gmail.com | E3: 9 | F3: 56637457 | G3: Astrada 508 | H3: 3754401018 | I3: Manualidades para niños | J3: Alias: avance.giro.final (titular: Graciela Silva)
A4: 45319.479 | B4: carogo12mez3@gmail.com | C4: Caarolina Ines Gomez | D4: carogo12mez3@gmail.com | E4: 26 | F4: 40410777 | G4: Calle córdoba 519, Leandro N Alem | H4: 3754495541 | I4: Corte y confección
A5: 45319.546 | B5: veronicagalarza705@gmail.com | C5: Veronica galarza | D5: Veronicagalarza705@gmail.com | E5: 30 | F5: 36470561 | G5: Calle el paraiso lote1 mz R | H5: 3754525043 | I5: Corte y confección
A6: 45321.375 | B6: mbareteviajesevt@gmail.com | C6: Dana milagros Diaz Martin | D6: mbareteviajesevt@gmail.com | E6: 15 | F6: 48889747 | G6: Corrientes 139 Leandro N Alem | H6: 3754528106 | I6: Canto
A7: 45322.808 | B7: guazzitizziano@gmail.com | C7: Emma Valentina Guazzi | D7: guazzitizziano@gmail.com | E7: 9 años | F7: 53790456 | G7: Barrio Virgen del Rosario W 5 | H7: 3704-810796 | I7: Manualidades para niños
A8: 45322.865 | B8: pedrozovivilore@gmail.com | C8: Balanda Leandro Miguel | D8: pedrozovivilore@gmail.com | E8: 11 años | F8: 52064374 | G8: Picada primero de mayo Lote 28 | H8: 3754-508532 | I8: Canto
A9: 45329.754 | B9: fernandarojasrios37@gmail.com | C9: Martina Florencia Rios | D9: fernandarojasrios37@gmail.com | E9: 12 | F9: 50940985 | G9: El Jacarandá 15 Alem | H9: 3755671228 | I9: Canto | J9: Si
A10: 45344.458 | B10: giselaalvez_15@hotmail.com | C10: Gisela Antonieta Alvez | D10: giselaalvez_15@hotmail.com | E10: 34 | F10: 34422662 | G10: Leandro. N. Alem | H10: 3754441492 | I10: Canto

Sheet Recibos
B1: ORIGINAL
G3: RECIBO
G4: Punto de Vta: 00002 Comp. Nro: | L4: ="0000"&COUNT(G43:G53)+1 -> 00002
B5: Razón Social: SILVA GRACIELA BEATRIZ | G5: Fecha de Emisión: | K5: =TODAY() -> 46197
B6: Domicilio Comercial: Cataratas Del Iguazú 912 - Leandro N. Alem | G6: CUIT: 27-25496483-8
C7: Misiones | G7: Ing. Brutos: 27-25496483-8
B8: Condición frente al IVA: Responsable Monotributo | G8: Inicio Actividades: 01/10/2020
B9: Documento no válido como Factura
B10: Alumno: | C10: Francisco Nestor | K10: DNI: | L10: =VLOOKUP(C10,formulario!C1:R1006,14,0) -> 55046930
B11: Domicilio: | C11: =VLOOKUP(C10,formulario!C1:J1006,4,0) -> Mecking 256 | K11: Teléfono: | L11: =VLOOKUP(C10,formulario!C1:J1006,5,0) -> 3754456868
B12: Nro de CUIT: | C12: =VLOOKUP(C10,formulario!C1:N1006,10,0) -> 34515584
B14: Mes | C14: Detalle / Servicio | L14: Importe
B16: Junio | C16: Servicios de Enseñanza Artística mes de: | F16: =B16& " 2026" -> Junio 2026 | L16: 25000
C17: Inscripción | L17: 20000
L27: =IF(B27="","",K27)
B29: Importe Total | K29: Pesos | L29: =SUM(L16:L28) -> 45000
B30: Cataratas del Iguazú 912 - Leandro N. Alem - Mnes. C.P. 3315 - Info: 3754 406435 / 499750
B36: Asunto: | C36: Recibo Instituto Superior de Danzas Folkloricas Argentinas
B37: Mensaje: | C37: ="Hola, "&G12&" “Como las hojas en otoño que caen para volver a renacer, cada paso en la danza folklórica guarda la memoria de quienes vinieron antes… y la fuerza de quienes siguen bailando hoy. 🍂💃" -> Hola, “Como las hojas en otoño que caen para volver a renacer, cada paso en la danza folklórica guarda la memoria de quienes vinieron antes… y la fuerza de quienes siguen bailando hoy. 🍂💃
B38: Destinatario: | C38: =VLOOKUP(C10,formulario!C1:J1006,2,0) -> neguikpp@gmail.com
B40: =K5 -> 46197 | C40: =C10 -> Francisco Nestor | D40: =B16 -> Junio | E40: =K5 -> 46197 | F40: =C17 -> Inscripción | G40: =L29 -> 45000
C43: =IFERROR(__xludf.DUMMYFUNCTION("filter(Pagos!B:F,C10=Pagos!B:B)"),"Francisco Nestor ") -> Francisco Nestor | D43: =IFERROR(__xludf.DUMMYFUNCTION("""COMPUTED_VALUE"""),"Junio") -> Junio | E43: =IFERROR(__xludf.DUMMYFUNCTION("""COMPUTED_VALUE"""),46196.0) -> 46196 | F43: =IFERROR(__xludf.DUMMYFUNCTION("""COMPUTED_VALUE"""),"Inscripción") -> Inscripción | G43: =IFERROR(__xludf.DUMMYFUNCTION("""COMPUTED_VALUE"""),45000.0) -> 45000

Sheet IDeIn
B1: ORIGINAL
G3: RECIBO
G4: Punto de Vta: 00002 Comp. Nro: | L4: ="0000"&COUNT(G32:G39)+1 -> 00001
B5: Razón Social: TURCHEÑUK PEDRO | G5: Fecha de Emisión: | K5: =TODAY() -> 46197
B6: Domicilio Comercial: Cataratas Del Iguazú 912 - Leandro N. Alem | G6: CUIT: 20-2309985-2
C7: Misiones | G7: Ing. Brutos: 20-23099805,2
B8: Condición frente al IVA: Responsable Monotributo | G8: Inicio Actividades: 01/03/1997
B9: Documento no válido como Factura
B10: Cliente: | C10: Instituto Santiago Canclini | K10: DNI:
B11: Domicilio: | C11: Maipu 1350 | K11: Teléfono:
B12: Nro de CUIT:
B14: Cantidd | C14: Detalle / Servicio | L14: Importe
B16: 2 | C16: armados e instalacion de CPU, Rizen | L16: 100000
B17: 2 | C17: Instalacion de 2 discos SSD 120Gb + instalación de sistema Operativo y Office | L17: 90000
L27: =IF(B27="","",K27)
B29: Importe Total | K29: Pesos | L29: =SUM(L16:L28) -> 190000
B30: Cataratas del Iguazú 912 - Leandro N. Alem - Mnes. C.P. 3315 - Info: 3754 406435 / 499750

Sheet ISC
A1: $ 100.000 secundaria | C1: Recibo X Nº1 | D1: 100000
A2: $ 90.000 primaria | C2: Recibo X Nº1 | D2: 90000
A4: Cuotas | C4: Marzo | D4: Abril | E4: Mayo
A5: $ 65.000 secundaria
A6: $ 60.000 primaria
A8: Material de Elena $ 110.000

Sheet Pagos
A1: 46091 | B1: Candela Jazmín Wach | C1: Marzo | D1: 46091 | E1: (1ra cuota Prof.) | F1: 40000
A2: 46091 | B2: Noa Samara Duran Quensell | C2: Marzo | D2: 46091 | E2: (inscripción y 1ra cuota) | F2: 45000
A3: 46091 | B3: Brenda Anahi Back | C3: Marzo | D3: 46091 | E3: (1ra cuota Prof.) | F3: 40000
A4: 46091 | B4: Alma Milenna Piñeiro | C4: Marzo | D4: 46091 | E4: (Inscripcion y 1ra cuota.) | F4: 45000
A5: 46091 | B5: Gianna Josefina Alarcón francesconi | C5: Marzo | D5: 46091 | E5: (Inscripcion) | F5: 20000
A6: 46091 | B6: Ona Guillermina Arndt | C6: Marzo | D6: 46091 | E6: (Inscripcion) | F6: 20000
A7: 46091 | B7: Gia Amelie | C7: Marzo | D7: 46091 | E7: (Inscripcion) | F7: 20000
A8: 46091 | B8: MELINA AYLÉN FERREIRA | C8: Marzo | D8: 46091 | E8: (Inscripcion) | F8: 20000
A9: 46093 | B9: Ana Paula Dallabrida | C9: Marzo | D9: 46093 | E9: (Inscripcion y 1ra cuota) | F9: 45000
A10: 46118 | B10: VICTORIA MACIEL KREISCHER | C10: Marzo | D10: 46118 | E10: (Inscripcion y 1ra cuota) | F10: 45000
A11: 46118 | B11: Zoe Alexia Frenna | C11: Marzo | D11: 46118 | E11: (Inscripcion y 1ra cuota) | F11: 60000
A12: 46120 | B12: Candela Jazmín Wach | C12: Abril | D12: 46120 | E12: 2da cuota) | F12: 40000
... A16: 46121 | B16: Isabella Hupan | C16: Abril | D16: 46121 | E16: Inscripción | F16: 17500
A17: 46132 | B17: Alma Milenna Piñeiro | C17: Abril | D17: 46132 | F17: 25000
A18: 46133 | B18: Ona Guillermina Arndt | C18: Abril | D18: 46133 | F18: 25000
A19: 46133 | B19: Gia Amelie | C19: Abril | D19: 46133 | F19: 12500
A20: 46133 | B20: Keyla Franco | C20: Marzo | D20: 46133 | E20: inscripción | F20: 40000
A21: 46146 | B21: Alma Milenna Piñeiro | C21: Mayo | D21: 46146 | F21: 25000
A22: 46146 | B22: Sanabria Benjamín Fernando | C22: Mayo | D22: 46146 | F22: 40000
A23: 46146 | B23: Sanabria Benjamín Fernando | C23: Abril | D23: 46146 | E23: Inscripcion | F23: 60000
A24: 46146 | B24: MELINA AYLÉN FERREIRA | C24: Abril | D24: 46146 | F24: 50000
A25: 46147 | B25: Benjamín Maximiliano Losanto | C25: Mayo | D25: 46147 | F25: 20000
A26: 46148 | B26: VICTORIA MACIEL KREISCHER | C26: Mayo | D26: 46148 | F26: 25000
A27: 46148 | B27: Romero Pona Luz Milagros | C27: Mayo | D27: 46148 | F27: 40000
A28: 46160 | B28: Ana Paula Dallabrida | C28: Mayo | D28: 46160 | F28: 25000
A29: 46160 | B29: Ana Paula Dallabrida | C29: Abril | D29: 46160 | F29: 25000
A30: 46174 | B30: VICTORIA MACIEL KREISCHER | C30: Junio | D30: 46174 | F30: 25000
A31: 46174 | B31: Alma Milenna Piñeiro | C31: Junio | D31: 46174 | F31: 25000
A32: 46177 | B32: Isabella Hupan | C32: Abril | D32: 46177 | F32: 25000
A33: 46177 | B33: Rocio Hupan | C33: Abril | D33: 46177 | F33: 25000
A34: 46177 | B34: Sol Betiana Yagus | C34: Junio | D34: 46177 | F34: 25000
A35: 46177 | B35: Sanabria Benjamín Fernando | C35: Junio | D35: 46177 | F35: 40000
... A42: 46181 | B42: Ciro Benjamín Nolasco | C42: Junio | D42: 46181 | F42: 25000
A43: 46196 | B43: Francisco Nestor | C43: Junio | D43: 46196 | E43: Inscripción | F43: 45000

Sheet Alumnos
B1: Apellido y Nombre | C1: Marca temporal | D1: Dirección de correo electrónico | E1: DNI | F1: F. de Nac | G1: Edad | H1: Domicilio | I1: Teléfono | J1: Ocupación | K1: Curso que Elige | L1: Localidad | N1: Matricula | O1: Marzo | P1: Abril | Q1: Mayo | R1: Junio | S1: Julio | T1: Agosto | U1: septiembre | V1: Octubre | W1: Noviembre | X1: Diciembre | Y1: Mes de inicio | Z1: Nro de Cuota | AA1: Dias y horarios de clases | AB1: Nivel
A2: 1 | B2: Alzugaray María Laura | C2: 7/28/2020 | D2: marialaura.alzugaray@gmail.com | E2: 37581526 | F2: 34174 | G2: 28 | H2: Barrio Illia casa N° 84 | I2: 3754472507 | J2: Docente | K2: Danzas Folkóricas Argentinas "Modalidad Acelerado" | L2: Leandro N. Alem | Z2: =COUNT(M2:X2) -> 0 | AA2: Martes y Jueves 18:00 - 20:00 hs | AB2: Segundo Preparatorio
A3: 2 | B3: Da Luz Facundo Manuel | C3: 2/18/2020 | D3: fdaluz83@gmail.com | E3: 30430962 | F3: 12/20/1983 | G3: 37 | H3: Felix Durán 449 | I3: 3754475271 | J3: Asesor crediticio | K3: Danzas Folkóricas Argentinas "Modalidad Acelerado" | L3: Leandro N. Alem | Z3: =COUNT(M3:X3) -> 0 | AA3: Martes y Jueves 18:00 - 20:00 hs | AB3: Primero Preparatorio
A4: 3 | B4: Leguizamón Flavia Beatriz | C4: 44424 | D4: flaviabeatrizleguizamon@gmail.com | E4: 41694880 | F4: 36250 | G4: 22 | H4: Bº Loteo Fao M8 S/n | I4: 3754465397 | K4: Danzas Folkóricas Argentinas "Modalidad Acelerado" | L4: Leandro N. Alem | Z4: =COUNT(M4:X4) -> 0 | AA4: Martes y Jueves 18:00 - 20:00 hs | AB4: Primer Año
A5: 4 | B5: Paniagua Nadia Belen | C5: 7/20/2020 | D5: centroesteticoalmabella@gmail.com | E5: 35006709 | F5: 33085 | G5: 31 | H5: Barrio Illia | I5: 3754461035 | J5: Docente | K5: Danzas Folkóricas Argentinas "Modalidad Acelerado" | L5: Leandro N. Alem | Z5: =COUNT(M5:X5) -> 0 | AA5: Martes y Jueves 18:00 - 20:00 hs | AB5: Segundo Preparatorio
A6: 5 | B6: Pinto Da Silva Florencia Guadalupe | C6: 1/30/2020 | D6: flor85pintodasilva@gmail.com | E6: 31572466 | F6: 31178 | G6: 36 | H6: San martin y fleming s/n | I6: 3754470782 | J6: Profesora de educacion fisica y preceptora | K6: Danzas Folkóricas Argentinas "Modalidad Acelerado" | L6: San Javier | Z6: =COUNT(M6:X6) -> 0 | AA6: Sábados de 08:00 - 12:00 hs | AB6: Tercero Preparatorio
A7: 6 | B7: Rodriguez de Olivera Solange María | C7: 44112 | D7: solangerodriguezdeolivera@gmail.com | E7: 34802897 | F7: 11/22/1990 | G7: 31 | H7: Itacaruaré | I7: 3754524721 | J7: Profesora de Nivel Inicial | K7: Danzas Folkóricas Argentinas "Modalidad Acelerado" | L7: Itacaruaré | Z7: =COUNT(M7:X7) -> 0 | AA7: Sábados de 08:00 - 12:00 hs | AB7: Segundo Preparatorio
A8: 7 | B8: Smorzeniuk yenifer de los angeles | C8: 43959 | D8: yenismorze@gmail.com | E8: 44389892 | F8: 10/13/2002 | G8: 19 | H8: 3 de febrero s/n Itacaruare | I8: 3754400694 | J8: Estudiante | K8: Danzas Folkóricas Argentinas "Modalidad Acelerado" | L8: Itacaruaré | Z8: =COUNT(M8:X8) -> 0 | AA8: Sábados de 08:00 - 12:00 hs | AB8: Segundo Preparatorio
A9: 8 | B9: Da Luz Uriel Ismael | C9: 44419 | D9: fdaluz83@gmail.com | F9: 40995 | G9: 7 | H9: Felix Duran 449 | K9: Danzas Folkóricas Argentinas infantil | L9: Leandro N. Alem | Z9: =COUNT(M9:X9) -> 0 | AA9: Miercoles 16:00 hs | AB9: Inicial
A10: 9 | B10: Llamosas Renata Valentina | C10: 44408 | D10: andreaferreiraa7@gmail.com | E10: 52309302 | F10: 41158 | G10: 9 | H10: Itacaruare | I10: 3754491063 | K10: Danzas Folkóricas Argentinas infantil | L10: Itacaruaré | Z10: =COUNT(M10:X10) -> 0 | AA10: Sabados 14:00 hs | AB10: Inicial
A11: 10 | B11: Losanto Benjamin Maximiliano | C11: 44777 | D11: marcelalosanto@hotmail.com | E11: 53796732 | F11: 41729 | G11: 8 | H11: Calle Bonpland 115 | I11: 3754432414 | K11: Danzas Folkóricas Argentinas infantil | L11: Leandro N. Alem
A12: 11 | B12: Losanto Pedrosky William Nahuel | C12: 44778 | D12: marcelalosanto@hotmail.com | E12: 54716260 | F12: 42151 | G12: 7 | H12: Calle Bonpland 115 | I12: 3754432414 | K12: Danzas Folkóricas Argentinas infantil | L12: Leandro N. Alem | AA12: Miercoles de 17:00 - 18:00 hs | AB12: Primero Preparatorio
A13: 12 | B13: Moschen Lucas Martin | C13: 44409 | D13: marianaalaniz82@gmail.com | E13: 53235744 | F13: 41506 | G13: 7 | H13: Otto Bar 62 | I13: 3755410502 | K13: Danzas Folkóricas Argentinas infantil | L13: Leandro N. Alem | Z13: =COUNT(M13:X13) -> 0 | AA13: Martes 16:00 Hs | AB13: 1er año Taller
A14: 13 | B14: Moschen Paula Antonella | C14: 44409 | D14: marianaalaniz82@gmail.com | E14: 55488253 | F14: 42514 | G14: 5 | H14: Otto Bar 62 | I14: 3755410502 | K14: Danzas Folkóricas Argentinas infantil | L14: Leandro N. Alem | Z14: =COUNT(M14:X14) -> 0 | AA14: Martes 16:00 Hs | AB14: 1er año Taller
A15: 14 | B15: =#REF! -> #REF! | C15: 45051 | D15: =#REF! -> #REF! | E15: =#REF! -> #REF! | F15: =#REF! -> #REF! | G15: =#REF! -> #REF! | H15: =#REF! -> #REF! | I15: =#REF! -> #REF! | K15: Danzas Folkóricas Argentinas infantil | L15: Leandro N. Alem
A16: 15 | B16: Paniagua Alma Isabela | C16: 44635 | D16: carlaasuncion@hotmail.com.ar | E16: 53092518 | F16: 41529 | G16: 8 | H16: Saavedra 112 | I16: 3754436602 | K16: Danzas Folkóricas Argentinas infantil | L16: Leandro N. Alem
A17: 16 | B17: Luz Milagros Pona Romero | C17: 44412 | D17: daniponna@gmail.com | E17: 53536539 | F17: 41600 | G17: 7 | H17: Bº Illia c109 | I17: 3754418757 | K17: Danzas Folkóricas Argentinas infantil | L17: Leandro N. Alem | Z17: =COUNT(M17:X17) -> 0 | AA17: Miercoles 16:00 hs | AB17: Inicial
A18: 17 | B18: Scromeda Dos Santos Abigail Ariadna | C18: 44223 | D18: Noeliads14@gmail.com | E18: 52303419 | F18: 41015 | G18: 9 | H18: Barrio 30 viv Jose Carlos Freaza casa 12 | I18: 3754416242 | K18: Danzas Folkóricas Argentinas infantil | L18: Itacaruaré
A19: 18 | B19: Tucheñuk Helena Anastasia | C19: 44419 | D19: gracielasilvatu3@gmail.com | E19: 53092554 | F19: 41549 | G19: 7 | H19: Cataratas del Iguazú 912 | I19: 3754499750 | J19: Profesora de Folklore | K19: Danzas Folkóricas Argentinas infantil | L19: Leandro N. Alem | Z19: =COUNT(M19:X19) -> 0 | AA19: Miercoles 16:00 hs | AB19: Inicial
A20: 19 | B20: Turcheñuk Josias Pablo | C20: 44419 | D20: ideincom@gmail.com | E20: 50559930 | F20: 40653 | G20: 10 | H20: Cataratas del Iguazú 912 | I20: 3754499750 | J20: Profesora de Folklore | K20: Danzas Folkóricas Argentinas infantil | L20: Leandro N. Alem | Z20: =COUNT(M20:X20) -> 0 | AA20: Miercoles 16:00 hs | AB20: Inicial
A21: 20 | B21: =#REF! -> #REF! | C21: 45050 | D21: =#REF! -> #REF! | E21: =#REF! -> #REF! | F21: =#REF! -> #REF! | G21: =#REF! -> #REF! | H21: =#REF! -> #REF! | I21: =#REF! -> #REF! | K21: Danzas Folkóricas Argentinas infantil | L21: Leandro N. Alem
A22: 21 | B22: Chales Gabriel Agustin | C22: 44431 | D22: Johanachales@gmail.com | F22: 41179 | G22: 9 | K22: Guitarra | L22: Leandro N. Alem | Z22: =COUNT(M22:X22) -> 0 | AA22: Lunes 18:30 hs | AB22: Guitarra
A23: 22 | B23: =#REF! -> #REF! | C23: 45053 | D23: =#REF! -> #REF! | E23: =#REF! -> #REF! | F23: =#REF! -> #REF! | G23: =#REF! -> #REF! | H23: =#REF! -> #REF! | I23: =#REF! -> #REF! | K23: =#REF! -> #REF! | L23: Leandro N. Alem
A24: 23 | B24: =#REF! -> #REF! | C24: 45054 | D24: =#REF! -> #REF! | E24: =#REF! -> #REF! | F24: =#REF! -> #REF! | G24: =#REF! -> #REF! | H24: =#REF! -> #REF! | I24: =#REF! -> #REF! | K24: =#REF! -> #REF! | L24: Leandro N. Alem
A25: 24 | B25: =#REF! -> #REF! | C25: 45073 | D25: =#REF! -> #REF! | E25: =#REF! -> #REF! | F25: =#REF! -> #REF! | G25: =#REF! -> #REF! | H25: =#REF! -> #REF! | I25: =#REF! -> #REF! | K25: =#REF! -> #REF! | L25: Leandro N. Alem
A26: 25 | B26: =#REF! -> #REF! | C26: 45072 | D26: =#REF! -> #REF! | E26: =#REF! -> #REF! | F26: =#REF! -> #REF! | G26: =#REF! -> #REF! | H26: =#REF! -> #REF! | I26: =#REF! -> #REF! | K26: =#REF! -> #REF! | L26: Leandro N. Alem
A27: 26 | B27: =#REF! -> #REF! | C27: 45069 | D27: =#REF! -> #REF! | E27: =#REF! -> #REF! | F27: =#REF! -> #REF! | G27: =#REF! -> #REF! | H27: =#REF! -> #REF! | I27: =#REF! -> #REF! | K27: =#REF! -> #REF! | L27: Leandro N. Alem
A28: 27 | B28: =#REF! -> #REF! | C28: 45066 | D28: =#REF! -> #REF! | E28: =#REF! -> #REF! | F28: =#REF! -> #REF! | G28: =#REF! -> #REF! | H28: =#REF! -> #REF! | I28: =#REF! -> #REF! | K28: =#REF! -> #REF! | L28: =#REF! -> #REF!
A29: 28 | B29: =#REF! -> #REF! | D29: =#REF! -> #REF! | E29: =#REF! -> #REF! | F29: =#REF! -> #REF! | G29: =#REF! -> #REF! | H29: =#REF! -> #REF! | I29: =#REF! -> #REF! | K29: =#REF! -> #REF! | L29: Leandro N. Alem
A30: 29 | B30: =#REF! -> #REF! | C30: 45063 | D30: =#REF! -> #REF! | E30: =#REF! -> #REF! | F30: =#REF! -> #REF! | G30: =#REF! -> #REF! | H30: =#REF! -> #REF! | I30: =#REF! -> #REF! | K30: =#REF! -> #REF! | L30: =#REF! -> #REF!
A31: 30 | B31: =#REF! -> #REF! | C31: 45058 | D31: =#REF! -> #REF! | E31: =#REF! -> #REF! | F31: =#REF! -> #REF! | G31: =#REF! -> #REF! | H31: =#REF! -> #REF! | I31: =#REF! -> #REF! | K31: =#REF! -> #REF! | L31: =#REF! -> #REF!
A32: 31 | B32: =#REF! -> #REF! | C32: 45074 | D32: =#REF! -> #REF! | E32: =#REF! -> #REF! | F32: =#REF! -> #REF! | G32: =#REF! -> #REF! | H32: =#REF! -> #REF! | I32: =#REF! -> #REF! | K32: Solo BAILAMOS | L32: Leandro N. Alem
A33: 32 | B33: =#REF! -> #REF! | C33: 45060 | D33: =#REF! -> #REF! | E33: =#REF! -> #REF! | F33: =#REF! -> #REF! | G33: =#REF! -> #REF! | H33: =#REF! -> #REF! | I33: =#REF! -> #REF! | K33: =#REF! -> #REF! | L33: =#REF! -> #REF!
A34: 33 | B34: =#REF! -> #REF! | D34: =#REF! -> #REF! | E34: =#REF! -> #REF! | F34: =#REF! -> #REF! | G34: =#REF! -> #REF! | H34: =#REF! -> #REF! | I34: =#REF! -> #REF! | K34: Solo BAILAMOS | L34: Leandro N. Alem
A35: 34 | B35: =#REF! -> #REF! | C35: 45059 | D35: =#REF! -> #REF! | E35: =#REF! -> #REF! | F35: =#REF! -> #REF! | G35: =#REF! -> #REF! | H35: =#REF! -> #REF! | I35: =#REF! -> #REF! | K35: =#REF! -> #REF! | L35: Leandro N. Alem
A36: 35 | B36: =#REF! -> #REF! | C36: 45061 | D36: =#REF! -> #REF! | E36: =#REF! -> #REF! | F36: =#REF! -> #REF! | G36: =#REF! -> #REF! | H36: =#REF! -> #REF! | I36: =#REF! -> #REF! | K36: =#REF! -> #REF! | L36: Leandro N. Alem
A37: 36 | B37: =#REF! -> #REF! | C37: 45068 | D37: =#REF! -> #REF! | E37: =#REF! -> #REF! | F37: =#REF! -> #REF! | G37: =#REF! -> #REF! | H37: =#REF! -> #REF! | I37: =#REF! -> #REF! | K37: =#REF! -> #REF! | L37: Leandro N. Alem
A38: 37 | B38: =#REF! -> #REF! | C38: 45064 | D38: =#REF! -> #REF! | E38: =#REF! -> #REF! | F38: =#REF! -> #REF! | G38: =#REF! -> #REF! | H38: =#REF! -> #REF! | I38: =#REF! -> #REF! | K38: =#REF! -> #REF! | L38: =#REF! -> #REF!
A39: 38 | B39: =#REF! -> #REF! | C39: 45071 | D39: =#REF! -> #REF! | E39: =#REF! -> #REF! | F39: =#REF! -> #REF! | G39: =#REF! -> #REF! | H39: =#REF! -> #REF! | I39: =#REF! -> #REF! | K39: =#REF! -> #REF! | L39: Leandro N. Alem
A40: 39 | B40: =#REF! -> #REF! | C40: 45070 | D40: =#REF! -> #REF! | E40: =#REF! -> #REF! | F40: =#REF! -> #REF! | G40: =#REF! -> #REF! | H40: =#REF! -> #REF! | I40: =#REF! -> #REF! | K40: =#REF! -> #REF! | L40: Leandro N. Alem
...

Sheet Examen
A1: =IFERROR(__xludf.DUMMYFUNCTION("IMPORTRANGE(""https://docs.google.com/spreadsheets/d/1h8i0mY2i70DSX-Sju4sC8Pudz_Rdlib8tF5tFWnSGdA"",""Respuestas!A:h"")"),"Marca temporal") -> Marca temporal | B1: =IFERROR(__xludf.DUMMYFUNCTION("""COMPUTED_VALUE"""),"Apellido y Nombre (cómo aparece en el DNI)") -> Apellido y Nombre (cómo aparece en el DNI) | C1: =IFERROR(__xludf.DUMMYFUNCTION("""COMPUTED_VALUE"""),"DNI") -> DNI | D1: =IFERROR(__xludf.DUMMYFUNCTION("""COMPUTED_VALUE"""),"Edad") -> Edad | E1: =IFERROR(__xludf.DUMMYFUNCTION("""COMPUTED_VALUE"""),"Sede a la que pertenece") -> Sede a la que pertenece | F1: =IFERROR(__xludf.DUMMYFUNCTION("""COMPUTED_VALUE"""),"Nivel que rinde [Preparatorio]") -> Nivel que rinde [Preparatorio] | G1: =IFERROR(__xludf.DUMMYFUNCTION("""COMPUTED_VALUE"""),"Nivel que rinde [Elemental]") -> Nivel que rinde [Elemental] | H1: =IFERROR(__xludf.DUMMYFUNCTION("""COMPUTED_VALUE"""),"Nivel que rinde [Superior]") -> Nivel que rinde [Superior]
A2: =IFERROR(__xludf.DUMMYFUNCTION("""COMPUTED_VALUE"""),45944.83512452546) -> 45944.835 | B2: =IFERROR(__xludf.DUMMYFUNCTION("""COMPUTED_VALUE"""),"Back Brenda Anahi ") -> Back Brenda Anahi | C2: =IFERROR(__xludf.DUMMYFUNCTION("""COMPUTED_VALUE"""),"52739073") -> 52739073 | D2: =IFERROR(__xludf.DUMMYFUNCTION("""COMPUTED_VALUE"""),12.0) -> 12 | E2: =IFERROR(__xludf.DUMMYFUNCTION("""COMPUTED_VALUE"""),"Alem") -> Alem | F2: =IFERROR(__xludf.DUMMYFUNCTION("""COMPUTED_VALUE"""),"Segundo") -> Segundo
A3: =IFERROR(__xludf.DUMMYFUNCTION("""COMPUTED_VALUE"""),45944.32252431713) -> 45944.323 | B3: =IFERROR(__xludf.DUMMYFUNCTION("""COMPUTED_VALUE"""),"Carolina Belén Rominski ") -> Carolina Belén Rominski | C3: =IFERROR(__xludf.DUMMYFUNCTION("""COMPUTED_VALUE"""),"43831994") -> 43831994 | D3: =IFERROR(__xludf.DUMMYFUNCTION("""COMPUTED_VALUE"""),23.0) -> 23 | E3: =IFERROR(__xludf.DUMMYFUNCTION("""COMPUTED_VALUE"""),"Alem") -> Alem | F3: =IFERROR(__xludf.DUMMYFUNCTION("""COMPUTED_VALUE"""),"Segundo") -> Segundo
A4: =IFERROR(__xludf.DUMMYFUNCTION("""COMPUTED_VALUE"""),45946.65316971065) -> 45946.653 | B4: =IFERROR(__xludf.DUMMYFUNCTION("""COMPUTED_VALUE"""),"Hanna Denise Machado") -> Hanna Denise Machado | C4: =IFERROR(__xludf.DUMMYFUNCTION("""COMPUTED_VALUE"""),"52809887") -> 52809887 | D4: =IFERROR(__xludf.DUMMYFUNCTION("""COMPUTED_VALUE"""),12.0) -> 12 | E4: =IFERROR(__xludf.DUMMYFUNCTION("""COMPUTED_VALUE"""),"Alem") -> Alem | F4: =IFERROR(__xludf.DUMMYFUNCTION("""COMPUTED_VALUE"""),"Segundo") -> Segundo
A5: =IFERROR(__xludf.DUMMYFUNCTION("""COMPUTED_VALUE"""),45944.78662118055) -> 45944.787 | B5: =IFERROR(__xludf.DUMMYFUNCTION("""COMPUTED_VALUE"""),"Pufal Mariana Elizabeth ") -> Pufal Mariana Elizabeth | C5: =IFERROR(__xludf.DUMMYFUNCTION("""COMPUTED_VALUE"""),"28539165") -> 28539165 | D5: =IFERROR(__xludf.DUMMYFUNCTION("""COMPUTED_VALUE"""),44.0) -> 44 | E5: =IFERROR(__xludf.DUMMYFUNCTION("""COMPUTED_VALUE"""),"Alem") -> Alem | F5: =IFERROR(__xludf.DUMMYFUNCTION("""COMPUTED_VALUE"""),"Segundo") -> Segundo
A6: =IFERROR(__xludf.DUMMYFUNCTION("""COMPUTED_VALUE"""),45944.32984788195) -> 45944.33 | B6: =IFERROR(__xludf.DUMMYFUNCTION("""COMPUTED_VALUE"""),"Wach Candela Jazmín ") -> Wach Candela Jazmín | C6: =IFERROR(__xludf.DUMMYFUNCTION("""COMPUTED_VALUE"""),"53090248") -> 53090248 | D6: =IFERROR(__xludf.DUMMYFUNCTION("""COMPUTED_VALUE"""),12.0) -> 12 | E6: =IFERROR(__xludf.DUMMYFUNCTION("""COMPUTED_VALUE"""),"Alem") -> Alem | F6: =IFERROR(__xludf.DUMMYFUNCTION("""COMPUTED_VALUE"""),"Segundo") -> Segundo
A7: =IFERROR(__xludf.DUMMYFUNCTION("""COMPUTED_VALUE"""),45944.93285814815) -> 45944.933 | B7: =IFERROR(__xludf.DUMMYFUNCTION("""COMPUTED_VALUE"""),"Benjamin Maximiliano Losanto") -> Benjamin Maximiliano Losanto | C7: =IFERROR(__xludf.DUMMYFUNCTION("""COMPUTED_VALUE"""),"53796732") -> 53796732 | D7: =IFERROR(__xludf.DUMMYFUNCTION("""COMPUTED_VALUE"""),11.0) -> 11 | E7: =IFERROR(__xludf.DUMMYFUNCTION("""COMPUTED_VALUE"""),"Alem") -> Alem | G7: =IFERROR(__xludf.DUMMYFUNCTION("""COMPUTED_VALUE"""),"Segundo") -> Segundo
A8: =IFERROR(__xludf.DUMMYFUNCTION("""COMPUTED_VALUE"""),45947.656347094904) -> 45947.656 | B8: =IFERROR(__xludf.DUMMYFUNCTION("""COMPUTED_VALUE"""),"Leites Franco Emmanuel ") -> Leites Franco Emmanuel | C8: =IFERROR(__xludf.DUMMYFUNCTION("""COMPUTED_VALUE"""),"34234803 ") -> 34234803 | D8: =IFERROR(__xludf.DUMMYFUNCTION("""COMPUTED_VALUE"""),31.0) -> 31 | E8: =IFERROR(__xludf.DUMMYFUNCTION("""COMPUTED_VALUE"""),"Alem") -> Alem | G8: =IFERROR(__xludf.DUMMYFUNCTION("""COMPUTED_VALUE"""),"Primero") -> Primero
A9: =IFERROR(__xludf.DUMMYFUNCTION("""COMPUTED_VALUE"""),45947.656347094904) -> 45947.656 | B9: =IFERROR(__xludf.DUMMYFUNCTION("""COMPUTED_VALUE"""),"Leites Franco Emmanuel ") -> Leites Franco Emmanuel | C9: =IFERROR(__xludf.DUMMYFUNCTION("""COMPUTED_VALUE"""),"34234803 ") -> 34234803 | D9: =IFERROR(__xludf.DUMMYFUNCTION("""COMPUTED_VALUE"""),31.0) -> 31 | E9: =IFERROR(__xludf.DUMMYFUNCTION("""COMPUTED_VALUE"""),"Alem") -> Alem | G9: =IFERROR(__xludf.DUMMYFUNCTION("""COMPUTED_VALUE"""),"Segundo") -> Segundo
A10: =IFERROR(__xludf.DUMMYFUNCTION("""COMPUTED_VALUE"""),45948.94379193287) -> 45948.944 | B10: =IFERROR(__xludf.DUMMYFUNCTION("""COMPUTED_VALUE"""),"Luz Milagros Pona Romero ") -> Luz Milagros Pona Romero | C10: =IFERROR(__xludf.DUMMYFUNCTION("""COMPUTED_VALUE"""),"53536539") -> 53536539 | D10: =IFERROR(__xludf.DUMMYFUNCTION("""COMPUTED_VALUE"""),11.0) -> 11 | E10: =IFERROR(__xludf.DUMMYFUNCTION("""COMPUTED_VALUE"""),"Alem") -> Alem | G10: =IFERROR(__xludf.DUMMYFUNCTION("""COMPUTED_VALUE"""),"Segundo") -> Segundo
A11: =IFERROR(__xludf.DUMMYFUNCTION("""COMPUTED_VALUE"""),45945.50250314815) -> 45945.503 | B11: =IFERROR(__xludf.DUMMYFUNCTION("""COMPUTED_VALUE"""),"Olexen Mariana Cinthia ") -> Olexen Mariana Cinthia | C11: =IFERROR(__xludf.DUMMYFUNCTION("""COMPUTED_VALUE"""),"42288209") -> 42288209 | D11: =IFERROR(__xludf.DUMMYFUNCTION("""COMPUTED_VALUE"""),25.0) -> 25 | E11: =IFERROR(__xludf.DUMMYFUNCTION("""COMPUTED_VALUE"""),"Alem") -> Alem | F11: =IFERROR(__xludf.DUMMYFUNCTION("""COMPUTED_VALUE"""),"Primero") -> Primero
A12: =IFERROR(__xludf.DUMMYFUNCTION("""COMPUTED_VALUE"""),45944.33147420139) -> 45944.331 | B12: =IFERROR(__xludf.DUMMYFUNCTION("""COMPUTED_VALUE"""),"Roballo Antonela Itatí ") -> Roballo Antonela Itatí | C12: =IFERROR(__xludf.DUMMYFUNCTION("""COMPUTED_VALUE"""),"41506733") -> 41506733 | D12: =IFERROR(__xludf.DUMMYFUNCTION("""COMPUTED_VALUE"""),27.0) -> 27 | E12: =IFERROR(__xludf.DUMMYFUNCTION("""COMPUTED_VALUE"""),"Alem") -> Alem | H12: =IFERROR(__xludf.DUMMYFUNCTION("""COMPUTED_VALUE"""),"Diploma") -> Diploma
A13: =IFERROR(__xludf.DUMMYFUNCTION("""COMPUTED_VALUE"""),45944.91907858796) -> 45944.919 | B13: =IFERROR(__xludf.DUMMYFUNCTION("""COMPUTED_VALUE"""),"Tereschuk Anibal Adrian") -> Tereschuk Anibal Adrian | C13: =IFERROR(__xludf.DUMMYFUNCTION("""COMPUTED_VALUE"""),"40197439") -> 40197439 | D13: =IFERROR(__xludf.DUMMYFUNCTION("""COMPUTED_VALUE"""),28.0) -> 28 | E13: =IFERROR(__xludf.DUMMYFUNCTION("""COMPUTED_VALUE"""),"Alem") -> Alem | F13: =IFERROR(__xludf.DUMMYFUNCTION("""COMPUTED_VALUE"""),"Primero") -> Primero
A14: =IFERROR(__xludf.DUMMYFUNCTION("""COMPUTED_VALUE"""),45947.72061549769) -> 45947.721 | B14: =IFERROR(__xludf.DUMMYFUNCTION("""COMPUTED_VALUE"""),"Yasmin Araceli Cerdan") -> Yasmin Araceli Cerdan | C14: =IFERROR(__xludf.DUMMYFUNCTION("""COMPUTED_VALUE"""),"53092552") -> 53092552 | D14: =IFERROR(__xludf.DUMMYFUNCTION("""COMPUTED_VALUE"""),12.0) -> 12 | E14: =IFERROR(__xludf.DUMMYFUNCTION("""COMPUTED_VALUE"""),"Alem") -> Alem | G14: =IFERROR(__xludf.DUMMYFUNCTION("""COMPUTED_VALUE"""),"Segundo") -> Segundo
A15: =IFERROR(__xludf.DUMMYFUNCTION("""COMPUTED_VALUE"""),45979.33452512731) -> 45979.335 | B15: =IFERROR(__xludf.DUMMYFUNCTION("""COMPUTED_VALUE"""),"Arndt Ona Guillermina") -> Arndt Ona Guillermina | C15: =IFERROR(__xludf.DUMMYFUNCTION("""COMPUTED_VALUE"""),"53785780") -> 53785780 | D15: =IFERROR(__xludf.DUMMYFUNCTION("""COMPUTED_VALUE"""),11.0) -> 11 | E15: =IFERROR(__xludf.DUMMYFUNCTION("""COMPUTED_VALUE"""),"Alem") -> Alem | F15: =IFERROR(__xludf.DUMMYFUNCTION("""COMPUTED_VALUE"""),"Segundo") -> Segundo
A16: =IFERROR(__xludf.DUMMYFUNCTION("""COMPUTED_VALUE"""),45979.3965162963) -> 45979.397 | B16: =IFERROR(__xludf.DUMMYFUNCTION("""COMPUTED_VALUE"""),"Frenna Zoe Alexia") -> Frenna Zoe Alexia | C16: =IFERROR(__xludf.DUMMYFUNCTION("""COMPUTED_VALUE"""),"53785766") -> 53785766 | D16: =IFERROR(__xludf.DUMMYFUNCTION("""COMPUTED_VALUE"""),11.0) -> 11 | E16: =IFERROR(__xludf.DUMMYFUNCTION("""COMPUTED_VALUE"""),"Alem") -> Alem | F16: =IFERROR(__xludf.DUMMYFUNCTION("""COMPUTED_VALUE"""),"Segundo") -> Segundo
A17: =IFERROR(__xludf.DUMMYFUNCTION("""COMPUTED_VALUE"""),45947.662856423616) -> 45947.663 | B17: =IFERROR(__xludf.DUMMYFUNCTION("""COMPUTED_VALUE"""),"Aguirre Guadalupe Xiomara ") -> Aguirre Guadalupe Xiomara | C17: =IFERROR(__xludf.DUMMYFUNCTION("""COMPUTED_VALUE"""),"55617160") -> 55617160 | D17: =IFERROR(__xludf.DUMMYFUNCTION("""COMPUTED_VALUE"""),9.0) -> 9 | E17: =IFERROR(__xludf.DUMMYFUNCTION("""COMPUTED_VALUE"""),"Arroyo del Medio") -> Arroyo del Medio | F17: =IFERROR(__xludf.DUMMYFUNCTION("""COMPUTED_VALUE"""),"Primero") -> Primero
A18: =IFERROR(__xludf.DUMMYFUNCTION("""COMPUTED_VALUE"""),45947.66467428241) -> 45947.665 | B18: =IFERROR(__xludf.DUMMYFUNCTION("""COMPUTED_VALUE"""),"Gimena Aylin Leites ") -> Gimena Aylin Leites | C18: =IFERROR(__xludf.DUMMYFUNCTION("""COMPUTED_VALUE"""),"54232826") -> 54232826 | D18: =IFERROR(__xludf.DUMMYFUNCTION("""COMPUTED_VALUE"""),10.0) -> 10 | E18: =IFERROR(__xludf.DUMMYFUNCTION("""COMPUTED_VALUE"""),"Arroyo del Medio") -> Arroyo del Medio | F18: =IFERROR(__xludf.DUMMYFUNCTION("""COMPUTED_VALUE"""),"Primero") -> Primero
A19: =IFERROR(__xludf.DUMMYFUNCTION("""COMPUTED_VALUE"""),45951.397326342594) -> 45951.397 | B19: =IFERROR(__xludf.DUMMYFUNCTION("""COMPUTED_VALUE"""),"Araujo Mariza Itatí ") -> Araujo Mariza Itatí | C19: =IFERROR(__xludf.DUMMYFUNCTION("""COMPUTED_VALUE"""),"36456529") -> 36456529 | D19: =IFERROR(__xludf.DUMMYFUNCTION("""COMPUTED_VALUE"""),32.0) -> 32 | E19: =IFERROR(__xludf.DUMMYFUNCTION("""COMPUTED_VALUE"""),"Cerro Azul") -> Cerro Azul | F19: =IFERROR(__xludf.DUMMYFUNCTION("""COMPUTED_VALUE"""),"Primero") -> Primero
A20: =IFERROR(__xludf.DUMMYFUNCTION("""COMPUTED_VALUE"""),45947.661569375) -> 45947.662 | B20: =IFERROR(__xludf.DUMMYFUNCTION("""COMPUTED_VALUE"""),"Báez Natali Yaquelin") -> Báez Natali Yaquelin | C20: =IFERROR(__xludf.DUMMYFUNCTION("""COMPUTED_VALUE"""),"43331812") -> 43331812 | D20: =IFERROR(__xludf.DUMMYFUNCTION("""COMPUTED_VALUE"""),24.0) -> 24 | E20: =IFERROR(__xludf.DUMMYFUNCTION("""COMPUTED_VALUE"""),"Cerro Azul") -> Cerro Azul | F20: =IFERROR(__xludf.DUMMYFUNCTION("""COMPUTED_VALUE"""),"Primero") -> Primero
A21: =IFERROR(__xludf.DUMMYFUNCTION("""COMPUTED_VALUE"""),45947.68593521991) -> 45947.686 | B21: =IFERROR(__xludf.DUMMYFUNCTION("""COMPUTED_VALUE"""),"Ferreyra Yesica Belén ") -> Ferreyra Yesica Belén | C21: =IFERROR(__xludf.DUMMYFUNCTION("""COMPUTED_VALUE"""),"36456601") -> 36456601 | D21: =IFERROR(__xludf.DUMMYFUNCTION("""COMPUTED_VALUE"""),32.0) -> 32 | E21: =IFERROR(__xludf.DUMMYFUNCTION("""COMPUTED_VALUE"""),"Cerro Azul") -> Cerro Azul | F21: =IFERROR(__xludf.DUMMYFUNCTION("""COMPUTED_VALUE"""),"Primero") -> Primero
A22: =IFERROR(__xludf.DUMMYFUNCTION("""COMPUTED_VALUE"""),45951.38710287037) -> 45951.387 | B22: =IFERROR(__xludf.DUMMYFUNCTION("""COMPUTED_VALUE"""),"Francesconi Agustina Nazarena ") -> Francesconi Agustina Nazarena | C22: =IFERROR(__xludf.DUMMYFUNCTION("""COMPUTED_VALUE"""),"42515020 ") -> 42515020 | D22: =IFERROR(__xludf.DUMMYFUNCTION("""COMPUTED_VALUE"""),25.0) -> 25 | E22: =IFERROR(__xludf.DUMMYFUNCTION("""COMPUTED_VALUE"""),"Cerro Azul") -> Cerro Azul | F22: =IFERROR(__xludf.DUMMYFUNCTION("""COMPUTED_VALUE"""),"Primero") -> Primero
A23: =IFERROR(__xludf.DUMMYFUNCTION("""COMPUTED_VALUE"""),45944.552513449074) -> 45944.553 | B23: =IFERROR(__xludf.DUMMYFUNCTION("""COMPUTED_VALUE"""),"Cardozo Gómez Fernández Sofía itati") -> Cardozo Gómez Fernández Sofía itati | C23: =IFERROR(__xludf.DUMMYFUNCTION("""COMPUTED_VALUE"""),"53537483") -> 53537483 | D23: =IFERROR(__xludf.DUMMYFUNCTION("""COMPUTED_VALUE"""),11.0) -> 11 | E23: =IFERROR(__xludf.DUMMYFUNCTION("""COMPUTED_VALUE"""),"Itacaruaré") -> Itacaruaré | F23: =IFERROR(__xludf.DUMMYFUNCTION("""COMPUTED_VALUE"""),"Primero") -> Primero
A24: =IFERROR(__xludf.DUMMYFUNCTION("""COMPUTED_VALUE"""),45947.76365172454) -> 45947.764 | B24: =IFERROR(__xludf.DUMMYFUNCTION("""COMPUTED_VALUE"""),"Kohl de Oliveira William ") -> Kohl de Oliveira William | C24: =IFERROR(__xludf.DUMMYFUNCTION("""COMPUTED_VALUE"""),"53785767") -> 53785767 | D24: =IFERROR(__xludf.DUMMYFUNCTION("""COMPUTED_VALUE"""),11.0) -> 11 | E24: =IFERROR(__xludf.DUMMYFUNCTION("""COMPUTED_VALUE"""),"Itacaruaré") -> Itacaruaré | F24: =IFERROR(__xludf.DUMMYFUNCTION("""COMPUTED_VALUE"""),"Primero") -> Primero
A25: =IFERROR(__xludf.DUMMYFUNCTION("""COMPUTED_VALUE"""),45947.741382314816) -> 45947.741 | B25: =IFERROR(__xludf.DUMMYFUNCTION("""COMPUTED_VALUE"""),"Medina Candela Lissel Oraide ") -> Medina Candela Lissel Oraide | C25: =IFERROR(__xludf.DUMMYFUNCTION("""COMPUTED_VALUE"""),"55777016 ") -> 55777016 | D25: =IFERROR(__xludf.DUMMYFUNCTION("""COMPUTED_VALUE"""),9.0) -> 9 | E25: =IFERROR(__xludf.DUMMYFUNCTION("""COMPUTED_VALUE"""),"Itacaruaré") -> Itacaruaré | F25: =IFERROR(__xludf.DUMMYFUNCTION("""COMPUTED_VALUE"""),"Primero") -> Primero
A26: =IFERROR(__xludf.DUMMYFUNCTION("""COMPUTED_VALUE"""),45950.38479863426) -> 45950.385 | B26: =IFERROR(__xludf.DUMMYFUNCTION("""COMPUTED_VALUE"""),"Pawluk Ghisleyne Mariel") -> Pawluk Ghisleyne Mariel | C26: =IFERROR(__xludf.DUMMYFUNCTION("""COMPUTED_VALUE"""),"55488299") -> 55488299 | D26: =IFERROR(__xludf.DUMMYFUNCTION("""COMPUTED_VALUE"""),9.0) -> 9 | E26: =IFERROR(__xludf.DUMMYFUNCTION("""COMPUTED_VALUE"""),"Itacaruaré") -> Itacaruaré | F26: =IFERROR(__xludf.DUMMYFUNCTION("""COMPUTED_VALUE"""),"Primero") -> Primero
A27: =IFERROR(__xludf.DUMMYFUNCTION("""COMPUTED_VALUE"""),45944.53577581019) -> 45944.536 | B27: =IFERROR(__xludf.DUMMYFUNCTION("""COMPUTED_VALUE"""),"Roballo Florencia Agustina") -> Roballo Florencia Agustina | C27: =IFERROR(__xludf.DUMMYFUNCTION("""COMPUTED_VALUE"""),"55777006") -> 55777006 | D27: =IFERROR(__xludf.DUMMYFUNCTION("""COMPUTED_VALUE"""),9.0) -> 9 | E27: =IFERROR(__xludf.DUMMYFUNCTION("""COMPUTED_VALUE"""),"Itacaruaré") -> Itacaruaré | F27: =IFERROR(__xludf.DUMMYFUNCTION("""COMPUTED_VALUE"""),"Primero") -> Primero
A28: =IFERROR(__xludf.DUMMYFUNCTION("""COMPUTED_VALUE"""),45944.48489047454) -> 45944.485 | B28: =IFERROR(__xludf.DUMMYFUNCTION("""COMPUTED_VALUE"""),"Rodríguez Sofia Itatí") -> Rodríguez Sofia Itatí | C28: =IFERROR(__xludf.DUMMYFUNCTION("""COMPUTED_VALUE"""),"53963778") -> 53963778 | D28: =IFERROR(__xludf.DUMMYFUNCTION("""COMPUTED_VALUE"""),9.0) -> 9 | E28: =IFERROR(__xludf.DUMMYFUNCTION("""COMPUTED_VALUE"""),"Itacaruaré") -> Itacaruaré | F28: =IFERROR(__xludf.DUMMYFUNCTION("""COMPUTED_VALUE"""),"Primero") -> Primero
A29: =IFERROR(__xludf.DUMMYFUNCTION("""COMPUTED_VALUE"""),45944.366519884265) -> 45944.367 | B29: =IFERROR(__xludf.DUMMYFUNCTION("""COMPUTED_VALUE"""),"Da Rosa Luz Morena ") -> Da Rosa Luz Morena | C29: =IFERROR(__xludf.DUMMYFUNCTION("""COMPUTED_VALUE"""),"52300816") -> 52300816 | D29: =IFERROR(__xludf.DUMMYFUNCTION("""COMPUTED_VALUE"""),13.0) -> 13 | E29: =IFERROR(__xludf.DUMMYFUNCTION("""COMPUTED_VALUE"""),"Itacaruaré") -> Itacaruaré | F29: =IFERROR(__xludf.DUMMYFUNCTION("""COMPUTED_VALUE"""),"Segundo") -> Segundo
A30: =IFERROR(__xludf.DUMMYFUNCTION("""COMPUTED_VALUE"""),45947.71577708333) -> 45947.716 | B30: =IFERROR(__xludf.DUMMYFUNCTION("""COMPUTED_VALUE"""),"Rodriguez Ludmara Gisahi ") -> Rodriguez Ludmara Gisahi | C30: =IFERROR(__xludf.DUMMYFUNCTION("""COMPUTED_VALUE"""),"51083733") -> 51083733 | D30: =IFERROR(__xludf.DUMMYFUNCTION("""COMPUTED_VALUE"""),14.0) -> 14 | E30: =IFERROR(__xludf.DUMMYFUNCTION("""COMPUTED_VALUE"""),"Itacaruaré") -> Itacaruaré | F30: =IFERROR(__xludf.DUMMYFUNCTION("""COMPUTED_VALUE"""),"Segundo") -> Segundo
A31: =IFERROR(__xludf.DUMMYFUNCTION("""COMPUTED_VALUE"""),45948.463588645835) -> 45948.464 | B31: =IFERROR(__xludf.DUMMYFUNCTION("""COMPUTED_VALUE"""),"Candia Sabrina Yazmin ") -> Candia Sabrina Yazmin | C31: =IFERROR(__xludf.DUMMYFUNCTION("""COMPUTED_VALUE"""),"52173063") -> 52173063 | D31: =IFERROR(__xludf.DUMMYFUNCTION("""COMPUTED_VALUE"""),13.0) -> 13 | E31: =IFERROR(__xludf.DUMMYFUNCTION("""COMPUTED_VALUE"""),"Itacaruaré") -> Itacaruaré | G31: =IFERROR(__xludf.DUMMYFUNCTION("""COMPUTED_VALUE"""),"Primero") -> Primero
A32: =IFERROR(__xludf.DUMMYFUNCTION("""COMPUTED_VALUE"""),45947.715852291665) -> 45947.716 | B32: =IFERROR(__xludf.DUMMYFUNCTION("""COMPUTED_VALUE"""),"Cavallo Ámbar Abril") -> Cavallo Ámbar Abril | C32: =IFERROR(__xludf.DUMMYFUNCTION("""COMPUTED_VALUE"""),"52449851") -> 52449851 | D32: =IFERROR(__xludf.DUMMYFUNCTION("""COMPUTED_VALUE"""),13.0) -> 13 | E32: =IFERROR(__xludf.DUMMYFUNCTION("""COMPUTED_VALUE"""),"Itacaruaré") -> Itacaruaré | G32: =IFERROR(__xludf.DUMMYFUNCTION("""COMPUTED_VALUE"""),"Primero") -> Primero
A33: =IFERROR(__xludf.DUMMYFUNCTION("""COMPUTED_VALUE"""),45947.740095810186) -> 45947.74 | B33: =IFERROR(__xludf.DUMMYFUNCTION("""COMPUTED_VALUE"""),"Medina Luisana Ailend") -> Medina Luisana Ailend | C33: =IFERROR(__xludf.DUMMYFUNCTION("""COMPUTED_VALUE"""),"52739062") -> 52739062 | D33: =IFERROR(__xludf.DUMMYFUNCTION("""COMPUTED_VALUE"""),12.0) -> 12 | E33: =IFERROR(__xludf.DUMMYFUNCTION("""COMPUTED_VALUE"""),"Itacaruaré") -> Itacaruaré | G33: =IFERROR(__xludf.DUMMYFUNCTION("""COMPUTED_VALUE"""),"Primero") -> Primero
A34: =IFERROR(__xludf.DUMMYFUNCTION("""COMPUTED_VALUE"""),45944.36437326389) -> 45944.364 | B34: =IFERROR(__xludf.DUMMYFUNCTION("""COMPUTED_VALUE"""),"Renata Valentina Llamosas ") -> Renata Valentina Llamosas | C34: =IFERROR(__xludf.DUMMYFUNCTION("""COMPUTED_VALUE"""),"52309302") -> 52309302 | D34: =IFERROR(__xludf.DUMMYFUNCTION("""COMPUTED_VALUE"""),13.0) -> 13 | E34: =IFERROR(__xludf.DUMMYFUNCTION("""COMPUTED_VALUE"""),"Itacaruaré") -> Itacaruaré | G34: =IFERROR(__xludf.DUMMYFUNCTION("""COMPUTED_VALUE"""),"Primero") -> Primero
A35: =IFERROR(__xludf.DUMMYFUNCTION("""COMPUTED_VALUE"""),45947.716001458335) -> 45947.716 | B35: =IFERROR(__xludf.DUMMYFUNCTION("""COMPUTED_VALUE"""),"Rizzello Valentina Aylen") -> Rizzello Valentina Aylen | C35: =IFERROR(__xludf.DUMMYFUNCTION("""COMPUTED_VALUE"""),"55343203") -> 55343203 | D35: =IFERROR(__xludf.DUMMYFUNCTION("""COMPUTED_VALUE"""),9.0) -> 9 | E35: =IFERROR(__xludf.DUMMYFUNCTION("""COMPUTED_VALUE"""),"Itacaruaré") -> Itacaruaré | G35: =IFERROR(__xludf.DUMMYFUNCTION("""COMPUTED_VALUE"""),"Primero") -> Primero
A36: =IFERROR(__xludf.DUMMYFUNCTION("""COMPUTED_VALUE"""),45947.93515608796) -> 45947.935 | B36: =IFERROR(__xludf.DUMMYFUNCTION("""COMPUTED_VALUE"""),"Rodríguez de Oliveira Solange María ") -> Rodríguez de Oliveira Solange María | C36: =IFERROR(__xludf.DUMMYFUNCTION("""COMPUTED_VALUE"""),"34802897") -> 34802897 | D36: =IFERROR(__xludf.DUMMYFUNCTION("""COMPUTED_VALUE"""),34.0) -> 34 | E36: =IFERROR(__xludf.DUMMYFUNCTION("""COMPUTED_VALUE"""),"Itacaruaré") -> Itacaruaré | H36: =IFERROR(__xludf.DUMMYFUNCTION("""COMPUTED_VALUE"""),"Diploma") -> Diploma
A37: =IFERROR(__xludf.DUMMYFUNCTION("""COMPUTED_VALUE"""),45944.45419179398) -> 45944.454 | B37: =IFERROR(__xludf.DUMMYFUNCTION("""COMPUTED_VALUE"""),"Rodríguez Do Santos Milagros Ludmila") -> Rodríguez Do Santos Milagros Ludmila | C37: =IFERROR(__xludf.DUMMYFUNCTION("""COMPUTED_VALUE"""),"53963725") -> 53963725 | D37: =IFERROR(__xludf.DUMMYFUNCTION("""COMPUTED_VALUE"""),10.0) -> 10 | E37: =IFERROR(__xludf.DUMMYFUNCTION("""COMPUTED_VALUE"""),"Itacaruaré") -> Itacaruaré | G37: =IFERROR(__xludf.DUMMYFUNCTION("""COMPUTED_VALUE"""),"Primero") -> Primero
A38: =IFERROR(__xludf.DUMMYFUNCTION("""COMPUTED_VALUE"""),45944.45523850694) -> 45944.455 | B38: =IFERROR(__xludf.DUMMYFUNCTION("""COMPUTED_VALUE"""),"Scromeda Do Santos Abigail Ariadna") -> Scromeda Do Santos Abigail Ariadna | C38: =IFERROR(__xludf.DUMMYFUNCTION("""COMPUTED_VALUE"""),"52303419") -> 52303419 | D38: =IFERROR(__xludf.DUMMYFUNCTION("""COMPUTED_VALUE"""),13.0) -> 13 | E38: =IFERROR(__xludf.DUMMYFUNCTION("""COMPUTED_VALUE"""),"Itacaruaré") -> Itacaruaré | G38: =IFERROR(__xludf.DUMMYFUNCTION("""COMPUTED_VALUE"""),"Primero") -> Primero
A39: =IFERROR(__xludf.DUMMYFUNCTION("""COMPUTED_VALUE"""),45947.71234034722) -> 45947.712 | B39: =IFERROR(__xludf.DUMMYFUNCTION("""COMPUTED_VALUE"""),"Sosa Aylen Elizabeth") -> Sosa Aylen Elizabeth | C39: =IFERROR(__xludf.DUMMYFUNCTION("""COMPUTED_VALUE"""),"52309305") -> 52309305 | D39: =IFERROR(__xludf.DUMMYFUNCTION("""COMPUTED_VALUE"""),13.0) -> 13 | E39: =IFERROR(__xludf.DUMMYFUNCTION("""COMPUTED_VALUE"""),"Itacaruaré") -> Itacaruaré | G39: =IFERROR(__xludf.DUMMYFUNCTION("""COMPUTED_VALUE"""),"Primero") -> Primero
A40: =IFERROR(__xludf.DUMMYFUNCTION("""COMPUTED_VALUE"""),45978.733970960646) -> 45978.734 | B40: =IFERROR(__xludf.DUMMYFUNCTION("""COMPUTED_VALUE"""),"Brenda Nacimento ") -> Brenda Nacimento | C40: =IFERROR(__xludf.DUMMYFUNCTION("""COMPUTED_VALUE"""),"53536509") -> 53536509 | D40: =IFERROR(__xludf.DUMMYFUNCTION("""COMPUTED_VALUE"""),12.0) -> 12 | E40: =IFERROR(__xludf.DUMMYFUNCTION("""COMPUTED_VALUE"""),"Itacaruaré") -> Itacaruaré | G40: =IFERROR(__xludf.DUMMYFUNCTION("""COMPUTED_VALUE"""),"Primero") -> Primero
...

Sheet formulario
A1: Marca temporal | B1: DNI | C1: Nombres y Apellido del Alumno | D1: Dirección de correo electrónico | E1: Edad | F1: Domicilio | G1: Teléfono de contacto | H1: Fecha de nacimiento | I1: Sede | J1: Talleres/Ballet | K1: Nivel | L1: NRO DE CUIT o DNI del Responsable (Padre, Madre o Tutor) | M1: Apellido y Nombre Responsable | N1: Curso / Nivel | O1: {=D:D} -> Dirección de correo electrónico | P1: {=B:B} -> DNI | Q1: Cuota
A2: 46050.716 | B2: 46388761 | C2: Naomi Nahir Gazal | D2: naogazal10@gmail.com | E2: 20 | F2: Barrio cámpora Mz H casa 4 | G2: 3754522753 | H2: 38392 | I2: Leandro N. Alem | J2: Ballet Bailar y Vivir | L2: 27463887611 | M2: Gazal Naomi | O2: naogazal10@gmail.com | P2: 46388761
A3: 46050.719 | B3: 42715605 | C3: Piñeiro Martín Alejandro | D3: martinchook17@gmail.com | E3: 25 | F3: Barrio cámpora Mz H casa 4 | G3: 3754439412 | H3: 36663 | I3: Leandro N. Alem | J3: Ballet Bailar y Vivir | L3: 20426156053 | M3: Piñeiro Martín | O3: martinchook17@gmail.com | P3: 42715605
A4: 46052.643 | B4: 55048458 | C4: Keyla Franco | D4: marianafranco1221@gmail.com | E4: 11 | F4: Barrio alem 2 casa 22 | G4: 3754533498 | H4: 42310 | I4: Leandro N. Alem | J4: Profesorado Infantil ( Desde 7 años) | K4: 1er Año Preparatorio | L4: 27364707490 | M4: Franco Mariana | O4: marianafranco1221@gmail.com | P4: 55048458
A5: 46058.431 | B5: 43528949 | C5: Cintia soledad Burg | D5: burgcintia1@gmail.com | E5: 25 | F5: Bonpland 311 | G5: 3754504509 | H5: 36595 | I5: Leandro N. Alem | J5: Profesorado/Instructorado Adultos (Desde 15 años) | K5: 1er Año Preparatorio | L5: 27435289490 | M5: Burg Cintia soledad | O5: burgcintia1@gmail.com | P5: 43528949
A6: 46062.521 | B6: 56240798 | C6: Tiziano Lautaro brites | D6: mcaraben@gmail.com | E6: 7 | F6: Barrio primero de mayo | G6: 3764759756 | H6: 43175 | I6: Cerro Azul | J6: Profesorado Infantil ( Desde 7 años) | K6: 1er Año Preparatorio | L6: 27392225388 | M6: Mariana Isabel caraben | O6: mcaraben@gmail.com | P6: 56240798
A7: 46062.693 | B7: 53796732 | C7: Benjamín Maximiliano Losanto | D7: marcelalosanto025@gmail.com | E7: 11 | F7: Bonpland 115 | G7: 3754432414 | H7: 41729 | I7: Leandro N. Alem | J7: Profesorado Infantil ( Desde 7 años) | K7: 3er Año Elemental | L7: 27419951787 | M7: Marcela Losanto | O7: marcelalosanto025@gmail.com | P7: 53796732
A8: 46062.811 | B8: 53090248 | C8: Candela Jazmín Wach | D8: rosciszewski22yamila@gmail.com | E8: 12 | F8: San Cayetano 228 | G8: 3754402554 | H8: 41379 | I8: Leandro N. Alem | J8: Profesorado Infantil ( Desde 7 años) | K8: 3er Año Preparatorio | L8: 27368931387 | M8: Rosciszewski Yamila | O8: rosciszewski22yamila@gmail.com | P8: 53090248
A9: 46071.468 | B9: 55617160 | C9: Guadalupe Xiomara Aguirre | D9: lilianabarboza57@gmail.com | E9: 9 | F9: Arroyo del medio lote 3 mzE | G9: 03754402825 | H9: 42682 | I9: Arroyo del Medio | J9: Profesorado Infantil ( Desde 7 años) | K9: 2do Año Preparatorio | L9: 23330733004 | M9: Barboza Liliana Ines | O9: lilianabarboza57@gmail.com | P9: 55617160
A10: 46077.496 | B10: 57607912 | C10: VICTORIA MACIEL KREISCHER | D10: soniakreischer@yahoo.com.ar | E10: 7 | F10: BUENOS AIRES 233 | G10: 3754478360 | H10: 43580 | I10: Leandro N. Alem | J10: Paisanitos ( Hasta 7 años Mixto) | L10: 27269872964 | M10: KREISCHER SONIA | O10: soniakreischer@yahoo.com.ar | P10: 57607912
A11: 46077.572 | B11: 52302885 | C11: Leite Triana Elizabeth | D11: roselizabert@gmail.com | E11: 13 | F11: Loteo fao lote 3 Mz 13 | G11: 3754457934 | H11: 41197 | I11: Leandro N. Alem | J11: Folklore un Lenguaje Artístico (+12) | L11: 27347947763 | M11: Leite Rosana Elizabet | O11: roselizabert@gmail.com | P11: 52302885
A12: 46077.641 | B12: 53785766 | C12: Zoe Alexia Frenna | D12: npf_886@hotmail.com | E12: 11 | F12: Avenida Güemes 678 | G12: 3754498204 | H12: 41850 | I12: Leandro N. Alem | J12: Folklore Creativo (-12) | L12: 31789982 | M12: Frenna Nicolás Paolo | O12: npf_886@hotmail.com | P12: 53785766
A13: 46077.792 | B13: 53785780 | C13: Ona Guillermina Arndt | D13: eugemino14@gmail.com | E13: 11 | F13: Juan Jose Paso 665 | G13: 3754431943 | H13: 41872 | I13: Leandro N. Alem | J13: Profesorado Infantil ( Desde 7 años) | K13: 3er Año Preparatorio | L13: 30078018 | M13: Miño Eugenia Ivana | O13: eugemino14@gmail.com | P13: 53785780
A14: 46077.866 | B14: 53536539 | C14: Romero Pona Luz Milagros | D14: maesro22romero@gmail.com | E14: 12 | F14: Barrio illia casa 109 | G14: 15466849 | H14: 41600 | I14: Leandro N. Alem | J14: Profesorado Infantil ( Desde 7 años) | K14: 3er Año Elemental | L14: 32609218 | M14: Romero Ester Pona Daniel | O14: maesro22romero@gmail.com | P14: 53536539
A15: 46079.675 | B15: 53785766 | C15: Zoe Alexia Frenna | D15: npf_886@hotmail.com | E15: 11 | F15: Avenida Güemes 678 Leandro N. Alem Misiones | G15: 3754498204 | H15: 40754 | I15: Leandro N. Alem | J15: Profesorado Infantil ( Desde 7 años) | K15: 3er Año Preparatorio | L15: 31789982 | M15: Frenna Nicolás Paolo | O15: npf_886@hotmail.com | P15: 53785766
A16: 46081.437 | B16: 56369053 | C16: Gia Amelie | D16: eugemino14@gmail.com | E16: 8 | F16: Juan jose paso 665 | G16: 3754431943 | H16: 42895 | I16: Leandro N. Alem | J16: Folklore Creativo (-12) | L16: 30078018 | M16: Miño Eugenia Ivana | O16: eugemino14@gmail.com | P16: 56369053
A17: 46081.757 | B17: 53796732 | C17: Benjamín Maximiliano Losanto | D17: marcelalosanto025@gmail.com | E17: 11 | F17: Bonpland 115 | G17: 3754432414 | H17: 41729 | I17: Leandro N. Alem | J17: Profesorado Infantil ( Desde 7 años) | K17: 3er Año Elemental | L17: 27419951787 | M17: Marcela yaquelin Losanto | O17: marcelalosanto025@gmail.com | P17: 53796732
A18: 46083.493 | B18: 52739073 | C18: Brenda Anahi Back | D18: sandraisabeldasilva1@gmail.com | E18: 13 | F18: Loteo Fao Lote 9 Mz6 | G18: 3754529218 | H18: 41241 | I18: Leandro N. Alem | J18: Folklore un Lenguaje Artístico (+12) | L18: 27330735355 | M18: Da Silva Sandra Isabel | O18: sandraisabeldasilva1@gmail.com | P18: 52739073
A19: 46083.699 | B19: 58733735 | C19: Noa Samara Duran Quensell | D19: silviaa.quensell@gmail.com | E19: 4 | F19: Juan Pablo ll Mz 143 casa 11 | G19: 3754451548 | H19: 44327 | I19: Leandro N. Alem | J19: Paisanitos ( Hasta 7 años Mixto) | L19: 32609356 | M19: Quensell silvia | O19: silviaa.quensell@gmail.com | P19: 58733735
A20: 46083.928 | B20: 53537483 | C20: Sofía Itati Cardozo Gómez Fernandez | D20: carlagofernandez1612@gmail.com | E20: 12 | F20: Itacaruare | G20: 3754495317 | H20: 41624 | I20: Itacaruaré | J20: Profesorado Infantil ( Desde 7 años) | K20: 2do Año Elemental | L20: 27372237444 | M20: Carla Gómez Fernandez | O20: carlagofernandez1612@gmail.com | P20: 53537483
A21: 46084.74 | B21: 52309302 | C21: Llamosas Renata Valentina | D21: andreaferreiraa7@gmail.com | E21: 13 | F21: Itacuruaré | G21: 3754491063 | H21: 41158 | I21: Itacaruaré | J21: Profesorado Infantil ( Desde 7 años) | K21: 2do Año Elemental | L21: 35012496 | M21: Ferreira Andrea Maricel | O21: andreaferreiraa7@gmail.com | P21: 52309302
A22: 46085.72 | B22: 55697881 | C22: Gianna Josefina Alarcón francesconi | D22: yan-y010@hotmail.com | E22: 9 | F22: San Javier 71 | G22: 3754526025 | H22: 42774 | I22: Leandro N. Alem | J22: Folklore Creativo (-12) | L22: 27311108243 | M22: Yanina Mariel francesconi | O22: yan-y010@hotmail.com | P22: 55697881
A23: 46088.373 | B23: 52300816 | C23: Da Rosa Luz Morena | D23: Marianadsrosa@gmail.com | E23: 14 | F23: Barrio El Progreso | G23: 3754436677 | H23: 40970 | I23: Itacaruaré | J23: Folklore un Lenguaje Artístico (+12) | L23: 32303956 | M23: Da Rosa Mariana | O23: Marianadsrosa@gmail.com | P23: 52300816
A24: 46088.721 | B24: 48266790 | C24: MELINA AYLÉN FERREIRA | D24: yaamiiisuarezz@gmail.com | E24: 18 | F24: Barrio ILLIA casa 128 | G24: 3754473017 | H24: 39485 | I24: Leandro N. Alem | J24: Profesorado/Instructorado Adultos (Desde 15 años) | K24: 1er Año Superior | L24: 31792126 | M24: SUÁREZ YAMILA | O24: yaamiiisuarezz@gmail.com | P24: 48266790
A25: 46090.414 | B25: 48266790 | C25: ferreira melina | D25: nelinferreira54@gmail.com | E25: 18 | F25: barrio illia 128 | G25: 3754473017 | H25: 39486 | I25: Leandro N. Alem | J25: Profesorado/Instructorado Adultos (Desde 15 años) | K25: 3er Año Elemental | L25: 31792126 | M25: yamila suarez | O25: nelinferreira54@gmail.com | P25: 48266790
A26: 46090.475 | B26: 41851970 | C26: Carballo Leonardo Sebastian | D26: leonardosebastiancarballo@gmail.com | E26: 26 | F26: Mayordomo olivera 1196 | G26: 3754406409 | H26: 36256 | I26: Leandro N. Alem | J26: Profesorado/Instructorado Adultos (Desde 15 años) | K26: 1er Año Elemental | L26: 41851970 | M26: Carballo Leonardo Sebastian | O26: leonardosebastiancarballo@gmail.com | P26: 41851970
A27: 46091.466 | B27: 58420837 | C27: Alma Milenna Piñeiro | D27: gladyspineiro92@gmail.com | E27: 5 | F27: Barrio Virgen del Rosario C.19 Mza B. Las Rosas L.N. Alem | G27: 3754525967 | H27: 44137 | I27: Leandro N. Alem | J27: Paisanitos ( Hasta 7 años Mixto) | L27: 45789908 | M27: Piñeiro Abril Soledad | O27: gladyspineiro92@gmail.com | P27: 58420837
A28: 46091.62 | B28: 55488299 | C28: Ghisleyne Mariel Pawluk | D28: carmenpolopawluk@gmail.com | E28: 9 | F28: Lote 632 (Itacaruare) | G28: 3754533553 | H28: 42583 | I28: Itacaruaré | J28: Profesorado Infantil ( Desde 7 años) | K28: 2do Año Preparatorio | L28: 27278880058 | M28: Polo, María del Carmen | O28: carmenpolopawluk@gmail.com | P28: 55488299
A29: 46091.874 | B29: 50662259 | C29: Piriz Horiana Nahiara | D29: horianapiriz@gmail.com | E29: 15 | F29: La corita | G29: 3758571983 | H29: 40553 | I29: La Corita | J29: Profesorado/Instructorado Adultos (Desde 15 años) | K29: 2do Año Preparatorio | L29: 31524709 | M29: Ferreira Andrea | O29: horianapiriz@gmail.com | P29: 50662259
A30: 46091.908 | B30: 55777006 | C30: Florencia Agustina Roballo | D30: fabiinesalvez@hotmail.com | E30: 9 | F30: Itacaruare Ruta Prov. N° 2 | G30: 3754402449 | H30: 42613 | I30: Itacaruaré | J30: Profesorado Infantil ( Desde 7 años) | K30: 2do Año Preparatorio | L30: 27326094612 | M30: Alvez Fabiana Ines | O30: fabiinesalvez@hotmail.com | P30: 55777006
A31: 46097.756 | B31: 58604845 | C31: Raffael Austyn Escalante | D31: rocio_noe25@outlook.com | E31: 5 | F31: Loteo Graf Lote U N°1 L.N.Alem | G31: 3764717379 | H31: 44251 | I31: Leandro N. Alem | J31: Paisanitos ( Hasta 7 años Mixto) | L31: 33926008 | M31: Márquez Rocío Noelia | O31: rocio_noe25@outlook.com | P31: 58604845
A32: 46098.836 | B32: 53796813 | C32: Thiago Francisco Ramos de matos | D32: roxanademattos@gmail.com | E32: 11 | F32: Itacaruare | G32: 3754527738 | H32: 41718 | I32: Itacaruaré | J32: Profesorado Infantil ( Desde 7 años) | K32: 1er Año Preparatorio | L32: 39225800 | M32: Roxana andrea ramos de matto | O32: roxanademattos@gmail.com | P32: 53796813
A33: 46100.542 | B33: 52301700 | C33: Xiomara Belen Aguilera | D33: britezmarina966@gmail.com | E33: 13 | F33: Mateo estacala RN°2 | G33: 3754478246 | H33: 41358 | I33: Itacaruaré | J33: Profesorado Infantil ( Desde 7 años) | K33: 1er Año Preparatorio | L33: 37325768 | M33: Britez marina mablel | O33: britezmarina966@gmail.com | P33: 52301700
A34: 46112.307 | B34: 34896657 | C34: Sanabria Benjamín Fernando | D34: fernalop90@gmail.com | E34: 10 | F34: Juana konopka y Unión nacional 1506 | G34: 3754434865 | H34: 42328 | I34: Leandro N. Alem | J34: Folklore un Lenguaje Artístico (+12) | L34: 27348966575 | M34: Piñeiro Fernanda Lorey | O34: fernalop90@gmail.com | P34: 34896657
A35: 46112.358 | B35: 53963778 | C35: Rodríguez Sofía Itati | D35: yaninaalmeida535@gmail.com | E35: 9 | F35: Manuel Alvares y Sarmiento | G35: 3754476413 | H35: 42514 | I35: Itacaruaré | J35: Profesorado Infantil ( Desde 7 años) | K35: 2do Año Preparatorio | L35: 27348968624 | M35: Almeida Yanina | O35: yaninaalmeida535@gmail.com | P35: 53963778
A36: 46113.897 | B36: 55777087 | C36: Ayala Erik Benjamin | D36: scromedavanessa@gmail.com | E36: 8 | F36: Calle San Lorenzo Itacaruaré | G36: 3754533742 | H36: 42858 | I36: Itacaruaré | J36: Folklore Creativo (-12) | L36: 37223782 | M36: Scromeda Vanesa/Ayala Jose Luis | O36: scromedavanessa@gmail.com | P36: 55777087
A37: 46114.549 | B37: 43331812 | C37: Natali Yaquelin Baez | D37: yaquelinbaez845@gmail.com | E37: 24 | F37: L.CROCCE S/N L-11 | G37: 3765075392 | H37: 46118 | I37: Cerro Azul | J37: Profesorado/Instructorado Adultos (Desde 15 años) | K37: 2do Año Preparatorio | L37: 28552258 | M37: Rosa Graciela Ramos | O37: yaquelinbaez845@gmail.com | P37: 43331812
A38: 46118.587 | B38: 37473721 | C38: Evelin Itatí Suarez | D38: eveliinszz@gmail.com | E38: 32 | F38: Sargento Cabral y Sarasola | G38: 3764728829 | H38: 34421 | I38: Cerro Azul | J38: Profesorado/Instructorado Adultos (Desde 15 años) | K38: 1er Año Preparatorio | L38: 37473721 | M38: Suarez Evelin Itatí | O38: eveliinszz@gmail.com | P38: 37473721
A39: 46118.597 | B39: 36456601 | C39: Yesica belen ferreyra | D39: yesicabelenferreyra5@gmail.com | E39: 32 | F39: Barrio sauer | G39: 3764672625 | H39: 38075 | I39: Cerro Azul | J39: Profesorado/Instructorado Adultos (Desde 15 años) | K39: 2do Año Preparatorio | L39: 27364566013 | M39: Ferreyra yesica belén | O39: yesicabelenferreyra5@gmail.com | P39: 36456601
A40: 46118.622 | B40: 36456529 | C40: Araujo Mariza Itatí | D40: marizaitatiaraujo@gmail.com | E40: 33 | F40: Cerro azul | G40: 3754527092 | H40: 34052 | I40: Cerro Azul | J40: Profesorado/Instructorado Adultos (Desde 15 años) | K40: 2do Año Preparatorio | L40: 27364565297 | M40: Araujo Mariza Itatí | O40: marizaitatiaraujo@gmail.com | P40: 36456529
...

Sheet Planilla San Javier
A1: Instituto Para el Desarrollo del Arte
A2: "Danzas Folkloricas Argentinas"
A3: PROFESORA: | B3: ANDREA ANDRIOLI
A4: Sede: | B4: SAN JAVIER
A5: Año: | B5: 2025
A8: Nivel | B8: Apellido y Nombre | C8: DNI | D8: Zapateo | E8: Zarandeo | F8: Teoría | G8: Posición | H8: Expresión | I8: Danza | J8: Prom/Final
A9: 1ro Preparatorio | B9: De Morais Keila Ayelen | C9: 54536877
A10: 1ro Preparatorio | B10: De Morais Ornela | C10: 50569580
A11: 1ro Preparatorio | B11: Rodríguez Héctor Leandro | C11: 54035639
A12: 1ro Preparatorio | B12: Vasquez Alba Elena | C12: 53795666
A13: 2do Preparatorio | B13: Ariana Aylin Galvan | C13: 54484198
A14: 2do Preparatorio | B14: de la Cruz Fernando Gabriel | C14: 52808423
A15: 2do Preparatorio | B15: De Mattos Renzo Nahuel | C15: 53540265
A16: 2do Preparatorio | B16: Diana Aylen Márquez | C16: 53536588
A17: 2do Preparatorio | B17: Indira Speyer | C17: 53795137
A18: 2do Preparatorio | B18: Mezetti Naieli Sofia | C18: 55699017
A19: 2do Preparatorio | B19: Segovia,Victoria Ayelen | C19: 55400685
A26: Observaciones
B30: =TODAY()+1 -> 46198
A37: ................................... | H37: ....................................

Sheet Planilla Itaca
A1: Instituto Para el Desarrollo del Arte
A2: "Danzas Folkloricas Argentinas"
A3: PROFESORA: | B3: SOLANGE RODRIGUEZ
A4: Sede: | B4: ITACARUARE
A5: Año: | B5: 2025
A8: Nivel | B8: Apellido y Nombre | C8: DNI | D8: Zapateo | E8: Zarandeo | F8: Teoría | G8: Posición | H8: Expresión | I8: Danza | J8: Prom/Final
A9: 1ro Preparatorio | B9: Cardozo Gómez Fernández Sofía itati | C9: 53537483
A10: 1ro Preparatorio | B10: Kohl de Oliveira William | C10: 53785767
A11: 1ro Preparatorio | B11: Medina Candela Lissel Oraide | C11: 55777016
A12: 1ro Preparatorio | B12: Pawluk Ghisleyne Mariel | C12: 55488299
A13: 1ro Preparatorio | B13: Roballo Florencia Agustina | C13: 55777006
A14: 1ro Preparatorio | B14: Rodríguez Sofia Itatí | C14: 53963778
A15: 2do Preparatorio | B15: Da Rosa Luz Morena | C15: 52300816
A16: 2do Preparatorio | B16: Rodriguez Ludmara Gisahi | C16: 51083733
A17: 1ro Elemental | B17: Candia Sabrina Yazmin | C17: 52173063
A18: 1ro Elemental | B18: Cavallo Ámbar Abril | C18: 52449851
A19: 1ro Elemental | B19: Medina Luisana Ailend | C19: 52739062
A20: 1ro Elemental | B20: Renata Valentina Llamosas | C20: 52309302
... A25: 1ro Elemental | B25: Brenda Nacimento | C25: 53536509
A27: Observaciones
B30: =TODAY()+1 -> 46198
A37: ................................... | H37: ....................................

Sheet Planilla Franco
A1: Instituto Para el Desarrollo del Arte
A2: "Danzas Folkloricas Argentinas"
A3: PROFESOR: | B3: FRANCO LEITES
A4: Sede: | B4: CERRO AZUL - ARROYO DEL MEDIO
A5: Año: | B5: 2025
A8: Nivel | B8: Apellido y Nombre | C8: DNI | D8: Zapateo | E8: Zarandeo | F8: Teoría | G8: Posición | H8: Expresión | I8: Danza | J8: Prom/Final
A9: 1ro Preparatorio | B9: Aguirre Guadalupe Xiomara | C9: 55617160
A10: 1ro Preparatorio | B10: Gimena Aylin Leites | C10: 54232826
A11: 1ro Preparatorio | B11: Araujo Mariza Itatí | C11: 36456529
A12: 1ro Preparatorio | B12: Báez Natali Yaquelin | C12: 43331812
A13: 1ro Preparatorio | B13: Ferreyra Yesica Belén | C13: 36456601
A14: 1ro Preparatorio | B14: Francesconi Agustina Nazarena | C14: 42515020
A27: Observaciones
B30: =TODAY()+1 -> 46198
A37: ................................... | H37: ....................................

Sheet Planilla Alem
A1: Instituto Para el Desarrollo del Arte
A2: "Danzas Folkloricas Argentinas"
A3: PROFESORAS: | B3: GRACIELA SILVA - MOIRA FRUTOS
A4: Sede: | B4: LEANDRO N. ALEM
A5: Año: | B5: 2025
A8: Nivel | B8: Apellido y Nombre | C8: DNI | D8: Zapateo | E8: Zarandeo | F8: Teoría | G8: Posición | H8: Expresión | I8: Danza | J8: Prom/Final
A9: 1ro Preparatorio | B9: Tereschuk Anibal Adrian | C9: 40197439
A10: 1ro Preparatorio | B10: Olexen Mariana Cinthia | C10: 42288209
A11: 2do Preparatorio | B11: Back Brenda Anahi | C11: 52739073
A12: 2do Preparatorio | B12: Carolina Belén Rominski | C12: 43831994
A13: 2do Preparatorio | B13: Hanna Denise Machado | C13: 52809887
A14: 2do Preparatorio | B14: Pufal Mariana Elizabeth | C14: 28539165
A15: 2do Preparatorio | B15: Wach Candela Jazmín | C15: 53090248
A16: 2do Preparatorio | B16: Arndt Ona Guillermina | C16: 53785780
A17: 2do Preparatorio | B17: Frenna Zoe Alexia | C17: 53785766
A18: 1ro Elemental | B18: Leites Franco Emmanuel | C18: 34234803
A19: 2do Elemental | B19: Leites Franco Emmanuel | C19: 34234803
A20: 2do Elemental | B20: Benjamin Maximiliano Losanto | C20: 53796732
A21: 2do Elemental | B21: Luz Milagros Pona Romero | C21: 53536539
A22: 2do Elemental | B22: Josías Pablo Turcheñuk | C22: 50939930
A23: 2do Elemental | B23: Helena Anastasia Turcheñuk | C23: 53092554
A24: 2do Elemental | B24: Yasmin Araceli Cerdan | C24: 53092552
A25: Diploma Superior | B25: Rodríguez de Oliveira Solange María | C25: 34802897
A26: Diploma Superior | B26: Roballo Antonela Itatí | C26: 41506733
A27: Observaciones
B30: =TODAY()+1 -> 46198
A37: ................................... | H37: ....................................

Sheet CUIT
